[2025-08-21 23:08:25] Starting CodePori (Proxy/Gemini) pipeline...
[2025-08-21 23:08:25] Proxy base: http://localhost:8000
[2025-08-21 23:08:25] Primary model: models/gemini-2.5-pro | Fallback: models/gemini-2.5-flash
[2025-08-21 23:08:25] Warning: could not reach proxy /health: HTTPConnectionPool(host='localhost', port=8000): Max retries exceeded with url: /health (Caused by NewConnectionError('<urllib3.connection.HTTPConnection object at 0x7f75a384afc0>: Failed to establish a new connection: [Errno 111] Connection refused'))
[2025-08-21 23:08:25] Primary model exception: HTTPConnectionPool(host='localhost', port=8000): Max retries exceeded with url: /v1beta/models/models/gemini-2.5-pro:generateContent (Caused by NewConnectionError('<urllib3.connection.HTTPConnection object at 0x7f75a37bf260>: Failed to establish a new connection: [Errno 111] Connection refused'))
[2025-08-21 23:08:25] Fallback model exception: HTTPConnectionPool(host='localhost', port=8000): Max retries exceeded with url: /v1beta/models/models/gemini-2.5-flash:generateContent (Caused by NewConnectionError('<urllib3.connection.HTTPConnection object at 0x7f75a37bf5c0>: Failed to establish a new connection: [Errno 111] Connection refused'))
[2025-08-21 23:08:25] FATAL: Manager/plan step returned no text.
Traceback (most recent call last):
  File "/home/runner/work/mocktests/mocktests/gemini-flask-57-2.py", line 443, in main
    plan_json = step_plan(model)
                ^^^^^^^^^^^^^^^^
  File "/home/runner/work/mocktests/mocktests/gemini-flask-57-2.py", line 196, in step_plan
    raise RuntimeError("Manager/plan step returned no text.")
RuntimeError: Manager/plan step returned no text.

